Workbook

Sheet Resumen
A1: Informe de Puntos e Incentivos por Marca
A2: Provexpress S.A.S. — corte a julio 2026
A4: Marca / Programa | B4: Recibido / cobrado (USD) | C4: Recibido / cobrado (COP) | D4: Pendiente / por canjear (USD) | E4: Pendiente / por canjear (COP)
A5: HPE Instant On | B5: ='HPE Instant On'!C11 -> 586 | C5: =B5*4000 -> 2344000 | D5: ='HPE Instant On'!C12 -> 242 | E5: =D5*4000 -> 968000
A6: HPE (tarjeta prepago) | B6: ='HPE Tarjeta'!B7 -> 300 | C6: ='HPE Tarjeta'!B8 -> 990000 | D6: 0 | E6: 0
A7: HP | B7: =HP!F10 -> 50057.2 | C7: =HP!B10 -> 184494002 | D7: 0 | E7: 0
A8: ASUS (cuota comercial AGP Silver)
A9: Lenovo (tarjeta prepago)Puntos | B9: ='Lenovo Tarjeta'!B5 -> 2200 | C9: ='Lenovo Tarjeta'!C15 -> 6395600 | D9: ='Lenovo Tarjeta'!B10 -> 622.05 | E9: =D9*3400 -> 2114970
A10: lenovo canales | B10: ='Lenovo Canales'!K24+'Lenovo Canales'!K25 -> 88799.52 | C10: ='Lenovo Canales'!K27 -> 3.1967827e+08
A11: Lenovo (canales - rebates) | B11: ='Lenovo Canales'!B16 -> 20633.9 | C11: ='Lenovo Canales'!C16 -> 74475266 | D11: ='Lenovo Canales'!B16 -> 20633.9 | E11: ='Lenovo Canales'!C16 -> 74475266
A12: Epson | B12: =Epson!D7+Epson!D10+Epson!D11+Epson!D12 -> 1324 | C12: =Epson!F13 -> 7455100 | D12: =Epson!B18 -> 12628000 | E12: =Epson!B18 -> 12628000
A13: Intel | B13: 0 | C13: 0 | D13: =Intel!D8/4000 -> 6228.75 | E13: =Intel!D8 -> 24915000
A14: Microsoft | B14: =Microsoft!C23 -> 20221.754 | C14: =Microsoft!B23 -> 80887014 | D14: =Microsoft!C24 -> 771.39432 | E14: =Microsoft!B24 -> 3085577.3
A15: Dell Rebates/MDF | B15: ='Dell Rebates'!F30 -> 49053.25 | C15: ='Dell Rebates'!G30 -> 176591700
A16: Dell MyRewards (puntos colaboradores)
A17: Zebra | B17: 0 | C17: 0 | D17: 0 | E17: 0
B18: =SUM(B5:B17) -> 233175.62 | C18: =SUM(C5:C17) -> 8.5331095e+08 | D18: =SUM(D5:D17) -> 12656498 | E18: =SUM(E5:E17) -> 1.1818681e+08
A21: Comparativo: valor recibido/cobrado por programa (USD)
A22: Programa | B22: USD
A23: HPE Instant On (confirmado) | B23: 828
A24: HPE tarjeta | B24: 300
A25: Lenovo tarjeta (recargas) | B25: 2200
A26: Lenovo canales (abr-jun 26 pagado) | B26: 20633.9
A27: Dell Rebates (pagado FY22-FY27 Q1) | B27: 176171.66
A30: Comparativo: valor en COP (recibido vs. pendiente)
A31: Concepto | B31: COP
A32: Epson - procesado | B32: 3726371
A33: Epson - pendiente | B33: 7797900
A34: Intel - pendiente | B34: 24915000
A35: Microsoft - 2025 | B35: 18594373
A36: Microsoft - 2026 (a jun) | B36: 62292641
A37: Microsoft - pendiente jul-26 | B37: 3085577.3
A38: HPE tarjeta - equivalente | B38: 990000
A39: HP - aprobado (3 trimestres) | B39: 99346574

Sheet HPE Instant On
A1: HPE Instant On
A2: Bonos en efectivo por redimir de incentivos (cash bonus cashout)
A4: Fecha | B4: Descripción | C4: Incentivo (USD) | D4: Estado | E4: ID de canje
A5: 2026-05-22 | B5: FY26Q2 Cash bonus cashout | C5: 242 | D5: Por canjear | E5: C260001217
A6: 2026-02-27 | B6: FY26Q1 Cash bonus cashout | C6: 95 | D6: Confirmado | E6: C260000530
A7: 2026-01-06 | B7: FY25Q4 Cash bonus cashout | C7: 88 | D7: Confirmado | E7: C260000111
A8: 2025-09-26 | B8: FY25Q3 Cash bonus cashout | C8: 403 | D8: Confirmado | E8: C250002268
A9: Total | C9: =SUM(C5:C8) -> 828
A11: Confirmados (con recibo) | C11: =SUMIF(D5:D8,"Confirmado",C5:C8) -> 586
A12: Por canjear (sin recibo aún) | C12: =SUMIF(D5:D8,"Por canjear",C5:C8) -> 242
A14: Confirmado vs. por canjear (USD)
A15: Estado | B15: USD
A16: Confirmado | B16: 828
A17: Por canjear | B17: =C5 -> 242
A18: Nota: el resultado de FY26Q2 (242 USD, may-2026) corresponde a gestión previa a la llegada de Jennifer.

Sheet HPE Tarjeta
A1: HPE
A2: Recompensa entregada — tarjeta prepago Visa
A4: Concepto | B4: Valor
A5: Recompensa entregada | B5: Physical Visa® Prepaid Card USD $300
A6: Fecha de entrega | B6: 2026-07-01
A7: Valor en USD | B7: 300
A8: Equivalente en COP | B8: 990000
A9: Puntos disponibles sin usar | B9: 390
A11: Nota: el valor de COP $990,000 corresponde al dato registrado en el archivo original para esta tarjeta.

Sheet HP
A1: HP
A2: Beneficios por trimestre — portal de incentivos HP (todos aprobados)
A4: Trimestre | B4: Obtenido hasta el momento (COP) | C4: Aprobado (COP) | D4: TRM usada (1 USD =) | E4: Estado | F4: usd
A5: Q2-2025 | B5: 14453256 | C5: 14453256 | D5: 4189 | E5: Aprobado | F5: =B5/D5 -> 3450.2879
A6: Q3-2025 | B6: 41246429 | C6: 41246429 | D6: 4223 | E6: Aprobado | F6: =B6/D6 -> 9767.0919
A7: Q4-2025 | B7: 43518360 | C7: 43518453 | D7: 4166 | E7: Aprobado | F7: =B7/D7 -> 10446.078
A8: Q1-2026 | B8: 58354399 | C8: 58354399 | D8: 3861 | E8: Aprobado | F8: =B8/D8 -> 15113.804
A9: Q2-2026 | B9: 41374814 | C9: 41374814 | D9: 3668 | E9: Aprobado | F9: =B9/D9 -> 11279.938
A10: Total | B10: =SUM(B6:B9) -> 184494002 | C10: =SUM(C6:C9) -> 184494095 | F10: =SUM(F5:F9) -> 50057.2
A12: Equivalente aproximado en USD (según TRM del portal)
A13: Trimestre | B13: USD aprox.
A14: Q2-2025 | B14: 14453256
A15: Q3-2025 | B15: 41246429
A16: Q4-2025 | B16: 43518360
A17: Q1-2026 | B17: 58354399
A18: Q2-2026 | B18: 41374814
A19: Nota: valores tomados directamente del portal de incentivos de HP (captura de pantalla). Q2-2025 y Q2-2026 corresponden a trimestres distintos (no acumulan entre sí). Se muestran duplicados en la captura original para el mismo trimestre; se tomó un solo registro por trimestre.

Sheet ASUS
A1: ASUS
A2: AGP Program 2026 — Reseller categoría AGP Silver
A4: Dato del programa | B4: Detalle
A5: Programa | B5: AGP Program 2026
A6: Categoría | B6: Reseller AGP Silver
A7: Cuota 2026 | B7: USD 200,000
A8: Unidades meta | B8: 345 unidades (Portátiles ASUS ExpertBook, AiO/Desktop ASUS ExpertCenter, Portátiles ASUS Chromebook)
A9: Aplica en compras a | B9: NEXSYS, INGRAM, MPS, IMPRESISTEM (mayoristas ASUS Business)
A10: KAM asignado | B10: Oscar Bolaños
A11: No aplica | B11: Portafolio de consumo: ASUS VivoBook, ZenBook, ROG, TUF, Monitores ASUS, Mini PCs / NUC
A14: Avance a corte del 30 de junio 2026
A15: Indicador | B15: Valor
A16: Ventas (ene-jun 2026) | B16: USD 38,472
A17: Unidades facturadas | B17: 60 unidades
A18: Cuota 2026 | B18: USD 200,000
A19: Cumplimiento al 30 de junio | B19: 19%
A20: Saldo restante para cumplir cuota | B20: USD 161,528
A23: Cumplimiento de cuota (USD)
A24: Concepto | B24: USD
A25: Vendido (ene-jun 2026) | B25: 38472
A26: Restante para cumplir cuota | B26: 161528
A28: Nota: esta cuota es una meta comercial de compras a mayoristas ASUS (no es un rebate ni puntos redimidos). El cumplimiento del 19% corresponde a la primera mitad del año 2026.

Sheet Lenovo Tarjeta
A1: Lenovo — Tarjeta prepago
A2: Recargas, consumo y comisiones (USD) + comparativo anual en COP
A4: Concepto | B4: USD | C4: Nota
A5: Total recargas | B5: 2200 | C5: Dinero que ha ingresado a la tarjeta
A6: Compras identificadas | B6: 1472.54 | C6: Consumo identificado en comercios
A7: Comisiones POS | B7: 49.5 | C7: Comisión cobrada por cada compra
A8: Comisiones recarga | B8: 16.51 | C8: Comisión cobrada por cada recarga
A9: Saldo teórico | B9: 661.45 | C9: Recargas - compras - comisiones
A10: Saldo disponible | B10: 622.05 | C10: Saldo real reportado por el banco
A11: Diferencia | B11: 39.4 | C11: Saldo teórico vs. disponible (por ajustar/revisar)
A13: Comparativo de consumo por año (COP)
A14: Año | B14: Total COP
A15: 2025 | B15: 2386800 | C15: =B15+B16 -> 6395600
A16: 2026 | B16: 4008800
A17: Variación 2025 → 2026 | B17: 0.67957097
A19: El consumo 2026 ya supera un 68% al de 2025 (a la fecha de corte).

Sheet Lenovo Canales
A1: Lenovo — Programa de canales (rebates)
A2: Historial anual + pagos confirmados abr-jun 2026 + detalle completo de transacciones (Program List Lenovo)
A4: Año | B4: Total (USD) | C4: Crecimiento
A5: 2023 | B5: 19962.95
A6: 2024 | B6: 58529.23 | C6: 1.931893
A7: 2025 | B7: 68165.62 | C7: 0.164642
A8: 2026 (proyección) | B8: 82535.6 | C8: 0.21081
A11: Ya pagado / cobrado — abr-jun 2026
A12: Programa | B12: USD | C12: COP
A13: Advocate CO 4Q FY26 IDG T2R | B13: 2000 | C13: 7102340
A14: Engage Platinum CO 4Q FY26 IDG T2 | B14: 16987.07 | C14: 61524789
A15: WKS Expert CO 4Q FY26 IDG T2 | B15: 1646.83 | C15: 5848137
A16: Total | B16: =SUM(B13:B15) -> 20633.9 | C16: =SUM(C13:C15) -> 74475266
A18: Nota: este bloque corresponde a los pagos ya confirmados y cobrados para el trimestre abril-junio 2026 (identificado en el archivo original como 'Q4_JAN_MAR' según la nomenclatura fiscal de Lenovo). Ver el detalle completo de las 32 transacciones históricas (jul-2023 a jun-2026) más abajo.
A21: Detalle completo de transacciones — histórico Lenovo (Program List)
A22: 32 registros del portal Lenovo LAS (Program List), todos con estado 'Pagado' · periodo FY24 Q2 (jul-2023) a FY26 Q4 (jun-2026)
A24: Fecha inicio | B24: Fecha fin | C24: Trimestre Lenovo | D24: Programa | E24: Familia | F24: Rebate (USD) | G24: Estado | H24: N° de referencia | J24: 2026 | K24: =F25+F26+F27 -> 20633.9
A25: 2026-01-01 | B25: 2026-03-31 | C25: Q4_JAN_MAR | D25: Engage Platinum CO 4Q FY26 IDG T2 | E25: Engage Platinum | F25: 16987.07 | G25: Pagado | H25: CCO10-SG63202512230039 | J25: 2025 | K25: =F28+F29+F30+F31+F32+F33+F34+F35+F36+F37+F38+F39+F40+F41 -> 68165.62
A26: 2026-01-01 | B26: 2026-03-31 | C26: Q4_JAN_MAR | D26: Advocate CO 4Q FY26 IDG T2R | E26: Advocate | F26: 2000 | G26: Pagado | H26: CCO10-SG63202512220002 | J26: Total | K26: =+K24+K25 -> 88799.52
A27: 2026-01-01 | B27: 2026-03-31 | C27: Q4_JAN_MAR | D27: WKS Expert CO 4Q FY26 IDG T2 | E27: WKS Expert | F27: 1646.83 | G27: Pagado | H27: CCO10-SG63202512240012 | K27: =K26*3600 -> 3.1967827e+08
A28: 2025-10-01 | B28: 2025-12-31 | C28: Q3_OCT_DEC | D28: Engage Platinum CO 3Q FY26 IDG T2 | E28: Engage Platinum | F28: 18423.11 | G28: Pagado | H28: CCO10-SG63202510100026
A29: 2025-10-01 | B29: 2025-12-31 | C29: Q3_OCT_DEC | D29: Advocate CO 3Q FY26 IDG T2 Reseller | E29: Advocate | F29: 2000 | G29: Pagado | H29: CCO10-SG63202511010002
A30: 2025-10-01 | B30: 2025-12-31 | C30: Q3_OCT_DEC | D30: WKS Expert CO 3Q FY26 IDG T2 | E30: WKS Expert | F30: 644.47 | G30: Pagado | H30: CCO10-SG63202510100014
A31: 2025-07-01 | B31: 2025-09-30 | C31: Q2_JUL_SEP | D31: Engage Platinum CO 2Q FY26 IDG T2 | E31: Engage Platinum | F31: 9654.04 | G31: Pagado | H31: CCO10-SG63202507110005
A32: 2025-07-01 | B32: 2025-09-30 | C32: Q2_JUL_SEP | D32: Advocate CO 2Q FY26 IDG T2 Reseller | E32: Advocate | F32: 2000 | G32: Pagado | H32: CCO10-SG63202507100011
A33: 2025-07-01 | B33: 2025-09-30 | C33: Q2_JUL_SEP | D33: BDF Platinum CO 2Q FY26 IDG T2 | E33: Engage BDF Platinum | F33: 1906.69 | G33: Pagado | H33: CCO10-SG63202507100015
A34: 2025-07-01 | B34: 2025-09-30 | C34: Q2_JUL_SEP | D34: WKS Expert CO 2Q FY26 IDG T2 | E34: WKS Expert | F34: 1774.24 | G34: Pagado | H34: CCO10-SG63202507100028
A35: 2025-04-01 | B35: 2025-06-30 | C35: Q1_APR_JUN | D35: Engage Platinum CO 1Q FY26 IDG T2 | E35: Engage Platinum | F35: 8793.44 | G35: Pagado | H35: CCO10-SG63202504230024
A36: 2025-04-01 | B36: 2025-06-30 | C36: Q1_APR_JUN | D36: Advocate CO 1Q FY26 IDG T2 | E36: Advocate | F36: 2000 | G36: Pagado | H36: CCO10-SG63202504230020
A37: 2025-04-01 | B37: 2025-06-30 | C37: Q1_APR_JUN | D37: WKS Expert CO 1Q FY26 IDG T2 | E37: WKS Expert | F37: 1271.5 | G37: Pagado | H37: CCO10-SG63202504230037
A38: 2025-01-01 | B38: 2025-03-31 | C38: Q4_JAN_MAR | D38: CO 4Q FY2425 Lenovo 360 Engage Program IDG Platinum T2 | E38: Engage Platinum | F38: 14327.5 | G38: Pagado | H38: CCO10-SG63202501080062
A39: 2025-01-01 | B39: 2025-03-31 | C39: Q4_JAN_MAR | D39: CO 4Q FY2425 Lenovo 360 Engage IDG BDF Platinum T2 | E39: Engage BDF Platinum | F39: 2802.29 | G39: Pagado | H39: CCO10-SG63202501080057
... A56: 2023-04-01 | B56: 2023-06-30 | C56: Q1_APR_JUN | D56: CO 1Q FY2324 Lenovo 360 Engage Program PCSD Gold | E56: Engage PCSD Gold | F56: 4104.34 | G56: Pagado | H56: CCO10-SG63202304040004
A57: Total | F57: =SUM(F25:F56) -> 167291.7
F58: =F57*3400 -> 568791780
A59: Desglose por familia de programa (histórico completo)
A61: Familia | B61: USD | C61: % del total
A62: Engage Platinum | B62: =SUMIF($E$25:$E$56,A62,$F$25:$F$56) -> 110432.89 | C62: =B62/$F$57 -> 0.66012175
A63: Engage PCSD Gold | B63: =SUMIF($E$25:$E$56,A63,$F$25:$F$56) -> 28613.63 | C63: =B63/$F$57 -> 0.17104034
A64: Advocate | B64: =SUMIF($E$25:$E$56,A64,$F$25:$F$56) -> 12000 | C64: =B64/$F$57 -> 0.071730994
...

Sheet Microsoft
A1: Microsoft — Commerce Incentives
A2: Revisión detallada por estado de pago (2025-2026)
A4: Fecha | B4: Cuenta | C4: Valor (COP) | D4: Estado
A5: 2025-08-12 | B5: Provexpress S.A.S | C5: 1151813.8 | D5: Pagado
A6: 2025-09-15 | B6: Provexpress S.A.S | C6: 14588853 | D6: Pagado
A7: 2025-10-14 | B7: Provexpress S.A.S (5014564) | C7: 1363343.1 | D7: Pagado
A8: 2025-10-14 | B8: Provexpress S.A.S (4850085) | C8: 1490362.9 | D8: Pagado
A9: 2026-01-16 | B9: Provexpress S.A.S (5014564) | C9: 3284256 | D9: Pagado
A10: 2026-01-16 | B10: Provexpress S.A.S (4850085) | C10: 20528015 | D10: Pagado
A11: 2026-02-15 | B11: Provexpress S.A.S | C11: 1720051.3 | D11: Pagado
A12: 2026-03-12 | B12: Provexpress S.A.S (5014564) | C12: 2930459.2 | D12: Pagado
A13: 2026-03-12 | B13: Provexpress S.A.S (4850085) | C13: 21243422 | D13: Pagado
A14: 2026-04-15 | B14: Provexpress S.A.S | C14: 1089888.7 | D14: Pagado
A15: 2026-05-13 | B15: Provexpress S.A.S | C15: 10003590 | D15: Pagado
A16: 2026-06-12 | B16: Provexpress S.A.S | C16: 1492958.7 | D16: Pagado
A17: 2026-07-09 | B17: Provexpress S.A.S | C17: 3085577.3 | D17: Upcoming (pendiente)
A18: Total | C18: =SUM(C5:C16) -> 80887014
A20: Resumen por estado — COP y USD (equivalente)
A22: Estado | B22: COP | C22: USD (aprox., TRM ~4000)
A23: Pagado (2025+2026) | B23: =SUMIF(D5:D17,"Pagado",C5:C17) -> 80887014 | C23: =B23/4000 -> 20221.754
A24: Pendiente (Upcoming, jul-2026) | B24: =SUMIF(D5:D17,"Upcoming (pendiente)",C5:C17) -> 3085577.3 | C24: =B24/4000 -> 771.39432
A25: Total | B25: =SUM(B23:B24) -> 83972592 | C25: =SUM(C23:C24) -> 20993.148
A27: Pagado por año (COP)
A28: Año | B28: COP
A29: 2025 | B29: 18594373
A30: 2026 (a jun, pagado) | B30: 62292641

Sheet Epson
A1: Epson
A2: Rebates por trimestre — procesados vs. pendientes
A4: Periodo | B4: Programa | C4: Mayorista | D4: Valor (USD) | E4: Estado
A5: 2026-04-01 a 2026-06-30 | B5: Consumo (Colombia) | C5: SED INTERNATIONAL DE COLOMBIA | D5: 1313 | E5: Pendiente | F5: 0 | G5: La marca paga al mayorista a finales de Julio
A6: 2026-01-01 a 2026-03-31 | B6: Consumo (Colombia) | C6: INGRAM MICRO S.A.S. | D6: 1050 | E6: Pendiente | F6: 0 | G6: a espera de informacion con respecto al mayorista que genera la NC
A7: 2026-01-01 a 2026-03-31 | B7: Comercial (Colombia) | C7: IMPRESISTEM S.A.S | D7: 546 | E7: Procesado | F7: 0
A8: 2025-10-01 a 2025-12-31 | B8: Comercial (Colombia) | C8: IMPRESISTEM S.A.S | D8: 444 | E8: Pendiente | F8: 2004371
A9: 2025-07-01 a 2025-09-30 | B9: Consumo (Colombia) | C9: IMPRESISTEM S.A.S | D9: 350 | E9: Pendiente | F9: 0
A10: 2025-07-01 a 2025-09-30 | B10: Comercial (Colombia) | C10: IMPRESISTEM S.A.S | D10: 420 | E10: Procesado | F10: 1722000
A11: 2025-03-31 a 2025-06-30 | B11: Consumo (Colombia) | C11: NEXSYS DE COLOMBIA S.A. | D11: 338 | E11: Procesado | F11: 3728729
A12: 2025-03-31 a 2025-06-30 | B12: Comercial (Colombia) | C12: NEXSYS DE COLOMBIA S.A. | D12: 20 | E12: Procesado
A13: Total | D13: =SUM(D5:D12) -> 4481 | F13: =SUM(F5:F12) -> 7455100
A15: Procesado vs. pendiente (COP)
A16: Estado | B16: COP
A17: Procesado | B17: 3726371
A18: Pendiente | B18: 12628000
B19: =D5+D6+D8+D9 -> 3157

Sheet Intel
A1: Intel
A2: Puntos redimidos y valor pendiente por cobrar
A4: Cantidad | B4: Valor unitario (USD) | C4: Valor total (USD) | D4: Valor en COP
A5: 1 | B5: 50 | C5: 50 | D5: 165000
A6: 5 | B6: 100 | C6: 500 | D6: 1650000
A7: 7 | B7: 1000 | C7: 7000 | D7: 23100000
A8: Total | C8: =SUM(C5:C7) -> 7550 | D8: =SUM(D5:D7) -> 24915000
A10: Todo el monto de Intel está pendiente por cobrar (COP $24,915,000).

Sheet Dell Rebates
B1: Dell — Rebates & MDF (Solution Provider)
B2: Reclamos por año fiscal, corte a jun-2026 (Claim Summary Report) — valores en USD y COP
A4: Año fiscal | B4: Q | C4: Programa | D4: Estado | E4: Aprobado (COP) | F4: Pagado (USD) | G4: Pagado (COP) | H4: TRM
A5: FY26 | B5: Q1 | C5: FY26Q1_Base_LATAM_Solution Provider_D | D5: Paid | E5: Complete | F5: 5532.54 | G5: =F5*H5 -> 19917144 | H5: 3600
A6: FY26 | B6: Q1 | C6: FY26Q1_eMDF_LATAM_SP | D6: Paid | E6: Complete | F6: 1871.82 | G6: =F6*H6 -> 6738552 | H6: 3600
A7: FY26 | B7: Q1 | C7: FY26Q1_Services_LATAM_Solution Provider_D | D7: Paid | E7: Complete | F7: 420.29 | G7: =F7*H7 -> 1513044 | H7: 3600
A8: FY26 | B8: Q2 | C8: FY25Q2_eMDF_LATAM_SP | D8: Paid | E8: Complete | F8: 1930.78 | G8: =F8*H8 -> 6950808 | H8: 3600
A9: FY26 | B9: Q2 | C9: FY26Q2_Base_LATAM_Solution Provider_D | D9: Paid | E9: Complete | F9: 5480.99 | G9: =F9*H9 -> 19731564 | H9: 3600
A10: FY26 | B10: Q2 | C10: FY26Q2_eMDF_LATAM_SP | D10: Paid | E10: Complete | F10: 1841.93 | G10: =F10*H10 -> 6630948 | H10: 3600
A11: FY26 | B11: Q2 | C11: FY26Q2_NBI_LATAM_Solution Provider_D | D11: Paid | E11: Complete | F11: 1405.08 | G11: =F11*H11 -> 5058288 | H11: 3600
A12: FY26 | B12: Q2 | C12: FY26Q2_Services_LATAM_Solution Provider_D | D12: Paid | E12: Complete | F12: 807.68 | G12: =F12*H12 -> 2907648 | H12: 3600
A13: FY26 | B13: Q3 | C13: FY25Q3_eMDF_LATAM_SP | D13: Paid | E13: Complete | F13: 1338.84 | G13: =F13*H13 -> 4819824 | H13: 3600
A14: FY26 | B14: Q3 | C14: FY26Q3_Base_LATAM_Solution Provider_D | D14: Paid | E14: Complete | F14: 4587.57 | G14: =F14*H14 -> 16515252 | H14: 3600
A15: FY26 | B15: Q3 | C15: FY26Q3_NBI_LATAM_Solution Provider_D | D15: Paid | E15: Complete | F15: 2322 | G15: =F15*H15 -> 8359200 | H15: 3600
A16: FY26 | B16: Q3 | C16: FY26Q3_Services_LATAM_Solution Provider_D | D16: Paid | E16: Complete | F16: 1580.75 | G16: =F16*H16 -> 5690700 | H16: 3600
... A19: FY26 | B19: Q4 | C19: FY26Q4_pbMDF_ISG | D19: Paid | E19: Complete | F19: 2000 | G19: =F19*H19 -> 7200000 | H19: 3600
A20: FY26 | B20: Q4 | C20: FY26Q4_Services_LATAM_Cloud Service Provider_D | D20: (en blanco) | E20: Declined | F20: $ - | G20: 0 | H20: 3600
A21: FY26 | B21: Q4 | C21: FY26Q4_Services_LATAM_Solution Provider_D | D21: Paid | E21: Complete | F21: 483.03 | G21: =F21*H21 -> 1738908 | H21: 3600
A22: FY27 | B22: Q1 | C22: FY27Q1_Base_LATAM_Cloud Service Provider_D | D22: (en blanco) | E22: Pending Final Review | F22: $ - | G22: 0 | H22: 3600
A23: FY27 | B23: Q1 | C23: FY27Q1_Base_LATAM_Solution Provider_D | D23: Paid | E23: Complete | F23: 8364.83 | G23: =F23*H23 -> 30113388 | H23: 3600
A24: FY27 | B24: Q1 | C24: FY27Q1_pbMDF_Client+ | D24: (en blanco) | E24: Released | F24: $ - | G24: 0 | H24: 3600
A25: FY27 | B25: Q1 | C25: FY27Q1_pbMDF_ISG | D25: (en blanco) | E25: Released | F25: $ - | G25: 0 | H25: 3600
A26: FY27 | B26: Q1 | C26: FY27Q1_Services_LATAM_Cloud Service Provider_D | D26: (en blanco) | E26: Pending Final Review | F26: $ - | G26: 0 | H26: 3600
A27: FY27 | B27: Q1 | C27: FY27Q1_Services_LATAM_Solution Provider_D | D27: Paid | E27: Complete | F27: 1289.08 | G27: =F27*H27 -> 4640688 | H27: 3600
A28: FY27 | B28: Q3 | C28: FY26Q3_eMDF_LATAM_SP | D28: (en blanco) | E28: Released | F28: $ - | G28: 0 | H28: 3600
A29: FY27 | B29: Q4 | C29: FY26Q4_Base_LATAM_Solution Provider_D | D29: Paid | E29: Complete | F29: 3407 | G29: =F29*H29 -> 12265200 | H29: 3600
B30: Total | C30: =SUM(C5:C29) -> 0 | D30: =SUM(D5:D29) -> 0 | E30: =SUM(E5:E29) -> 0 | F30: =SUM(F5:F29) -> 49053.25 | G30: =SUM(G5:G29) -> 176591700
B32: Resumen por estado (USD y COP)
B33: Estado | C33: USD | D33: COP
A34: FY26 | B34: Q1 | C34: =F5+F6+F7 -> 7824.65 | D34: =G5+G6+G7 -> 28168740
A35: FY26 | B35: Q2 | C35: =F8+F9+F10+F11+F12 -> 11466.46 | D35: =G8+G9+G10+G11+G12 -> 41279256
A36: FY26 | B36: Q3 | C36: =F13+F14+F15+F16 -> 9829.16 | D36: =SUM(G13:G16) -> 35384976
A37: FY26 | B37: Q4 | C37: =SUM(F17:F21) -> 6872.07 | D37: =SUM(G17:G21) -> 24739452
A38: FY27 | B38: Q1 | C38: =F23+F27 -> 9653.91 | D38: =G23+G27 -> 34754076
A39: FY27 | B39: Q3 | C39: 0
A40: FY27 | B40: Q4 | C40: =F29 -> 3407 | D40: =G29 -> 12265200
B41: Total | C41: =SUM(C34:C40) -> 49053.25 | D41: =SUM(D34:D40) -> 176591700
B44: Execution Year | C44: Fund Quarter | D44: Fund Name | E44: Claim Payment Status | F44: Claim Status Name | G44: Suma de Approved to Pay
B45: FY26 | C45: Q1 | D45: FY26Q1_Base_LATAM_Solution Provider_D | E45: Paid | F45: Complete | G45: 5532.54
D46: FY26Q1_eMDF_LATAM_SP | E46: Paid | F46: Complete | G46: 1871.82
...

Sheet Dell MyRewards
A1: Dell — MyRewards (puntos de colaboradores)
A3: Resumen por estado
A5: Puntos pendientes por reclamar, por trimestre de venta
A6: Trimestre | B6: Puntos pendientes
A7: Etiquetas de fila | B7: Suma de MyR Points
A8: FY22-Q1 | B8: 50
A9: FY22-Q2 | B9: 415
A10: FY22-Q3 | B10: 540
A11: FY22-Q4 | B11: 375
A12: FY23-Q1 | B12: 135
A13: FY23-Q2 | B13: 120
A14: FY23-Q3 | B14: 490
A15: FY23-Q4 | B15: 420
A16: FY24-Q1 | B16: 65
A17: FY24-Q2 | B17: 715
A18: FY24-Q3 | B18: 505
A19: FY24-Q4 | B19: 1342
... A29: Total general | B29: 12905

Sheet Zebra
A1: Zebra
A2: Sin datos disponibles
A4: Esta marca figura en el archivo original sin información cargada todavía.
A5: En cuanto haya movimientos de puntos o rebates, se pueden agregar aquí siguiendo el mismo formato de las demás hojas.
